Workbook

Sheet Cover
A1: Costco Wholesale Corporation (COST): Equity Research and Valuation Model
A2: Independent academic research and valuation case study; not investment advice.
A3: Valuation date: 31 January 2025. Only information public on that date is used. Author: Pooja Master.
A5: Headline outputs
A6: Active scenario | B6: =Assumptions!D5 -> Base
A7: WACC | B7: =DCF!B8 -> 0.083824806
A8: Terminal growth | B8: =DCF!B9 -> 0.03
A9: Enterprise value ($m) | B9: =DCF!B40 -> 145270.53
A10: DCF value per share ($) | B10: =DCF!B48 -> 336.68367
A11: Share price, 31 Jan 2025 ($) | B11: =DCF!B49 -> 979.88
A12: Upside / (downside) | B12: =DCF!B50 -> -0.65640316
A13: Model checks | B13: =Checks!E22 -> ALL OK
A15: Sheets
A16: Historicals | B16: FY2019-FY2024 statements from 10-K XBRL; comments give the source of every number
A17: Assumptions | B17: Forecast drivers with rationale; scenario switch in C5 (1 Bear, 2 Base, 3 Bull)
A18: Forecast | B18: Integrated income statement, balance sheet and cash flow; balance check
A19: Beta | B19: 60-month regression of Costco vs. S&P 500 returns
A20: WACC | B20: CAPM, cost of debt, market-value weights
A21: DCF | B21: UFCF, stub and mid-year timing, value-driver terminal value, equity bridge
A22: Sensitivity | B22: Live WACC x g and RONIC x g grids; revenue x margin and scenario tables
A23: Comps | B23: Peer multiples, quartiles and implied Costco value
A24: Summary | B24: Football-field table
A25: Checks | B25: Integrity checks and reconciliation to the Python pipeline
A27: Colour legend
A28: 1,234 | B28: Blue: hardcoded input (sourced in a comment or note)
A29: 1,234 | B29: Black: formula
A30: 1,234 | B30: Green: link to another sheet
A31: 1,234 | B31: Yellow fill: key assumption or output
A33: Built by src/build_excel.py in github.com/pooja003-cloud/costco-equity-research-valuation

Sheet Historicals
A1: Historical financial statements, FY2019-FY2024 ($ millions)
A2: Independent academic research and valuation case study; not investment advice.
A3: Source: Costco 10-K inline XBRL via src/extract_financials.py. Each value has a comment with its XBRL concept, filing accession and a link to the tagged fact.
A5: $ millions, fiscal years ending ~31 Aug | B5: FY2019 | C5: FY2020 | D5: FY2021 | E5: FY2022 | F5: FY2023 | G5: FY2024
A6: Income statement
A7: Net sales | C7: 163220 | D7: 192052 | E7: 222730 | F7: 237710 | G7: 249625
A8: Membership fees | C8: 3541 | D8: 3877 | E8: 4224 | F8: 4580 | G8: 4828
A9: Total revenue | C9: 166761 | D9: 195929 | E9: 226954 | F9: 242290 | G9: 254453
A10: Merchandise costs | C10: 144939 | D10: 170684 | E10: 199382 | F10: 212586 | G10: 222358
A11: Selling, general and administrative | C11: 16387 | D11: 18537 | E11: 19779 | F11: 21590 | G11: 22810
A12: Preopening expenses (in SG&A from FY2022 presentation) | C12: 0 | D12: 0 | E12: 0 | F12: 0 | G12: 0
A13: Operating income | C13: 5435 | D13: 6708 | E13: 7793 | F13: 8114 | G13: 9285
A14: Interest expense | C14: 160 | D14: 171 | E14: 158 | F14: 160 | G14: 169
A15: Interest income and other, net | C15: 92 | D15: 143 | E15: 205 | F15: 533 | G15: 624
A16: Income before income taxes | C16: 5367 | D16: 6680 | E16: 7840 | F16: 8487 | G16: 9740
A17: Provision for income taxes | C17: 1308 | D17: 1601 | E17: 1925 | F17: 2195 | G17: 2373
A18: Net income including noncontrolling interests | C18: 4059 | D18: 5079 | E18: 5915 | F18: 6292 | G18: 7367
... A24: Weighted avg. shares - diluted (m) | C24: 443.901 | D24: 444.346 | E24: 444.757 | F24: 444.452 | G24: 444.759
A26: Balance sheet
A27: Cash and cash equivalents | B27: 8384 | C27: 12277 | D27: 11258 | E27: 10203 | F27: 13700 | G27: 9906
A28: Short-term investments | B28: 1060 | C28: 1028 | D28: 917 | E28: 846 | F28: 1534 | G28: 1238
A29: Receivables, net | B29: 1535 | C29: 1550 | D29: 1803 | E29: 2241 | F29: 2285 | G29: 2721
A30: Merchandise inventories | B30: 11395 | C30: 12242 | D30: 14215 | E30: 17907 | F30: 16651 | G30: 18647
A31: Other current assets | B31: 1111 | C31: 1023 | D31: 1312 | E31: 1499 | F31: 1709 | G31: 1734
A32: Total current assets | B32: 23485 | C32: 28120 | D32: 29505 | E32: 32696 | F32: 35879 | G32: 34246
A33: Property and equipment, net | B33: 20890 | C33: 21807 | D33: 23492 | E33: 24646 | F33: 26684 | G33: 29032
A34: Operating lease right-of-use assets | B34: 0 | C34: 2788 | D34: 2890 | E34: 2774 | F34: 2713 | G34: 2617
A35: Other long-term assets | B35: 1025 | C35: 2841 | D35: 3381 | E35: 4050 | F35: 3718 | G35: 3936
A36: Total assets | B36: 45400 | C36: 55556 | D36: 59268 | E36: 64166 | F36: 68994 | G36: 69831
A37: Accounts payable | B37: 11679 | C37: 14172 | D37: 16278 | E37: 17848 | F37: 17483 | G37: 19421
A38: Accrued salaries and benefits | B38: 3176 | C38: 3605 | D38: 4090 | E38: 4381 | F38: 4278 | G38: 4794
... A52: Common shares outstanding (m) | B52: 439.625 | C52: 441.255 | D52: 441.825 | E52: 442.664 | F52: 442.793 | G52: 443.126
A54: Cash flow
A55: Net cash provided by operating activities | C55: 8861 | D55: 8958 | E55: 7392 | F55: 11068 | G55: 11339
A56: Depreciation and amortization | C56: 1645 | D56: 1781 | E56: 1900 | F56: 2077 | G56: 2237
A57: Stock-based compensation | C57: 619 | D57: 665 | E57: 724 | F57: 774 | G57: 818
A58: (Increase) decrease in merchandise inventories | C58: 791 | D58: 1892 | E58: 4003 | F58: -1228 | G58: 2068
A59: Increase in accounts payable | C59: 2261 | D59: 1838 | E59: 1891 | F59: -382 | G59: 1938
A60: Other operating assets and liabilities, net | C60: -728 | D60: -1057 | E60: -549 | F60: -172 | G60: -741
A61: Additions to property and equipment | C61: 2810 | D61: 3588 | E61: 3891 | F61: 4323 | G61: 4710
...

Sheet Assumptions
A1: Forecast and valuation assumptions (FY2025-FY2029)
A2: Independent academic research and valuation case study; not investment advice.
A3: Values and rationale mirror config/assumptions.json, config/valuation.json and config/scenarios.json. Change blue cells; the model updates.
A5: Scenario selector (1 = Bear, 2 = Base, 3 = Bull) | C5: 2 | D5: =CHOOSE($C$5,"Bear","Base","Bull") -> Base
A7: Driver | B7: Unit | C7: FY2025E | D7: FY2026E | E7: FY2027E | F7: FY2028E | G7: FY2029E | H7: Rationale / source
A8: Net new warehouses | B8: count | C8: =CHOOSE($C$5,C9,C10,C11) -> 26 | D8: =CHOOSE($C$5,D9,D10,D11) -> 27 | E8: =CHOOSE($C$5,E9,E10,E11) -> 27 | F8: =CHOOSE($C$5,F9,F10,F11) -> 27 | G8: =CHOOSE($C$5,G9,G10,G11) -> 27 | H8: FY2025: management plans 29 openings including 3 relocations, so 26 net (Q1 FY2025 10-Q). FY2026-29: 27 a year, the average of FY2024 actual (29) and FY2025 plan (26). This is above the FY2021-23 pace of 20-23 because the opening pipeline has accelerated.
A9: Bear | C9: 26 | D9: 22 | E9: 22 | F9: 22 | G9: 22
A10: Base | C10: 26 | D10: 27 | E10: 27 | F10: 27 | G10: 27
A11: Bull | C11: 26 | D11: 30 | E11: 30 | F11: 30 | G11: 30
A13: Comparable sales growth (reported) | B13: % | C13: =CHOOSE($C$5,C14,C15,C16) -> 0.055 | D13: =CHOOSE($C$5,D14,D15,D16) -> 0.05 | E13: =CHOOSE($C$5,E14,E15,E16) -> 0.045 | F13: =CHOOSE($C$5,F14,F15,F16) -> 0.04 | G13: =CHOOSE($C$5,G14,G15,G16) -> 0.04 | H13: Reported comps, including gasoline and FX. Q1 FY2025 total comps were 5% (7% excl. gas & FX; lower gas prices and a stronger dollar held the reported number back). FY2025 is set at 5.5%, assuming these headwinds ease a little. The rate then fades to 4.0% by FY2028: roughly 2-2.5% inflation plus 1.5-2% traffic and market-share gains. That is below the FY2023-24 ex-gas/FX run-rate of 5-6% and the FY2016-19 pre-pandemic average of about 5%, because a larger base makes high comps harder to sustain.
A14: Bear | C14: 0.045 | D14: 0.035 | E14: 0.03 | F14: 0.025 | G14: 0.025
A15: Base | C15: 0.055 | D15: 0.05 | E15: 0.045 | F15: 0.04 | G15: 0.04
A16: Bull | C16: 0.06 | D16: 0.06 | E16: 0.055 | F16: 0.05 | G16: 0.05
A18: Paid member growth | B18: % | C18: =CHOOSE($C$5,C19,C20,C21) -> 0.07 | D18: =CHOOSE($C$5,D19,D20,D21) -> 0.065 | E18: =CHOOSE($C$5,E19,E20,E21) -> 0.06 | F18: =CHOOSE($C$5,F19,F20,F21) -> 0.055 | G18: =CHOOSE($C$5,G19,G20,G21) -> 0.05 | H18: Year-end paid members grew 6-8% a year in FY2021-24, averaging 7.0%, and were up 7.5% year on year at Q1 FY2025 (77.4m vs 72.0m). Growth fades toward 5% as more new warehouses open in existing markets, which lowers the member uplift per opening (a point the 10-Q itself makes).
A19: Bear | C19: 0.06 | D19: 0.05 | E19: 0.045 | F19: 0.04 | G19: 0.04
A20: Base | C20: 0.07 | D20: 0.065 | E20: 0.06 | F20: 0.055 | G20: 0.05
A21: Bull | C21: 0.075 | D21: 0.07 | E21: 0.065 | F21: 0.06 | G21: 0.06
A23: Gross margin on net sales | B23: % | C23: =CHOOSE($C$5,C24,C25,C26) -> 0.11 | D23: =CHOOSE($C$5,D24,D25,D26) -> 0.11 | E23: =CHOOSE($C$5,E24,E25,E26) -> 0.11 | F23: =CHOOSE($C$5,F24,F25,F26) -> 0.11 | G23: =CHOOSE($C$5,G24,G25,G26) -> 0.11 | H23: FY2024 was 10.92%. Q1 FY2025 rose 24bp year on year (7bp excluding gasoline deflation), helped by core merchandise mix and the co-branded credit card. The model holds 11.0%, at the upper end of the FY2020-24 range (10.5-11.2%). The model assumes no further expansion because Costco reinvests margin in price, and the higher Executive reward cap ($1,250 from $1,000) is a small cost.
A24: Bear | C24: 0.1085 | D24: 0.1085 | E24: 0.1085 | F24: 0.1085 | G24: 0.1085
A25: Base | C25: 0.11 | D25: 0.11 | E25: 0.11 | F25: 0.11 | G25: 0.11
A26: Bull | C26: 0.111 | D26: 0.111 | E26: 0.111 | F26: 0.111 | G26: 0.111
A28: SG&A % of net sales | B28: % | C28: =CHOOSE($C$5,C29,C30,C31) -> 0.092 | D28: =CHOOSE($C$5,D29,D30,D31) -> 0.092 | E28: =CHOOSE($C$5,E29,E30,E31) -> 0.092 | F28: =CHOOSE($C$5,F29,F30,F31) -> 0.092 | G28: =CHOOSE($C$5,G29,G30,G31) -> 0.092 | H28: FY2024 was 9.14%. Q1 FY2025 was 14bp higher year on year, flat excluding gasoline deflation. The model holds 9.20%: wage investment and technology spend offset further operating leverage. This deliberately assumes no additional SG&A leverage, even though SG&A fell from 10.0% to 9.1% of net sales over FY2020-24.
A29: Bear | C29: 0.093 | D29: 0.093 | E29: 0.093 | F29: 0.093 | G29: 0.093
A30: Base | C30: 0.092 | D30: 0.092 | E30: 0.092 | F30: 0.092 | G30: 0.092
A31: Bull | C31: 0.0915 | D31: 0.0915 | E31: 0.0915 | F31: 0.0915 | G31: 0.0915
A34: Single-value drivers
A35: New-warehouse productivity (x unit growth) | B35: x | C35: 0.65 | D35: 0.65 | E35: 0.65 | F35: 0.65 | G35: 0.65 | H35: New warehouses open below the fleet average and ramp up over several years. Historically, net sales growth not explained by comps was about 0.6-0.7x net unit growth (FY2021 0.66, FY2022 0.70, FY2023 0.63, FY2024 0.60). Growth from new warehouses = 0.65 x net unit growth.
A36: Fee increase on affected fees | B36: % | C36: 0.0833 | D36: 0.0833 | E36: 0.0833 | F36: 0.0833 | G36: 0.0833 | H36: $60 to $65 and $120 to $130 (+8.3%), FY2024 10-K
A37: Share of fee income affected (U.S. & Canada) | B37: % | C37: 0.85 | D37: 0.85 | E37: 0.85 | F37: 0.85 | G37: 0.85 | H37: Effective 1 Sep 2024, the U.S./Canada Gold Star and Business fee rose from $60 to $65 (+8.3%) and the Executive fee from $120 to $130 (+8.3%), as disclosed in the FY2024 10-K. Affected share = 85%, a proxy based on U.S. and Canada being 86% of revenue (Costco does not split fee income by segment). Fees are recognized over the 12-month membership term and renewals are spread across the year, so about half the uplift lands in FY2025 and the rest in FY2026. Net effect: fee per member +3.5% in FY2025 and +3.5% in FY2026.
A38: Share of fee increase recognised in year | B38: % | C38: 0.5 | D38: 0.5 | E38: 0 | F38: 0 | G38: 0 | H38: Fees are recognised ratably over the 12-month membership; renewals are spread through the year
A39: Other fee-per-member growth | B39: % | C39: 0 | D39: 0 | E39: 0 | F39: 0 | G39: 0 | H39: Apart from fee increases, fee income per average paid member was flat at about $65-66 in FY2021-24: more Executive upgrades were offset by growth in lower-fee international members. The next fee increase (historically every 5.5-7 years: 2011, 2017, 2024) would fall around FY2030-31, after the explicit forecast, so it is not included. It is an upside to the terminal value.
A40: Tax rate | B40: % | C40: 0.26 | D40: 0.26 | E40: 0.26 | F40: 0.26 | G40: 0.26 | H40: Effective rate excluding discrete items was 25.9-26.6% in FY2020-24 (26.4% in FY2024). Recurring stock-compensation deductions trim a few tenths off in most years, so the model uses 26.0% on both NOPAT and net income.
A41: D&A % of beginning net PP&E | B41: % | C41: 0.084 | D41: 0.084 | E41: 0.084 | F41: 0.084 | G41: 0.084 | H41: D&A as a share of beginning net PP&E was 8.2%, 8.1%, 8.4% and 8.4% in FY2021-24. Linking D&A to the asset base keeps capex and depreciation consistent.
A42: Capex % of revenue (FY2026+) | B42: % | C42: 0.0185 | D42: 0.0185 | E42: 0.0185 | F42: 0.0185 | G42: 0.0185 | H42: FY2025: management's stated plan of about $5.0bn (Q1 FY2025 10-Q). FY2026-29: 1.85% of revenue, in line with FY2021-24 (1.71-1.85%) and consistent with about 27 openings a year plus remodels, depots and technology.
A43: Capex FY2025 (management plan) | B43: $m | C43: 5000
A44: Receivables % revenue | B44: % | C44: 0.01069 | D44: 0.01069 | E44: 0.01069 | F44: 0.01069 | G44: 0.01069 | H44: Held at FY2024 ratio
A45: Inventories % revenue | B45: % | C45: 0.07328 | D45: 0.07328 | E45: 0.07328 | F45: 0.07328 | G45: 0.07328 | H45: Held at FY2024 ratio
A46: Other current assets % revenue | B46: % | C46: 0.00681 | D46: 0.00681 | E46: 0.00681 | F46: 0.00681 | G46: 0.00681 | H46: Held at FY2024 ratio
A47: Accounts payable % revenue | B47: % | C47: 0.07632 | D47: 0.07632 | E47: 0.07632 | F47: 0.07632 | G47: 0.07632 | H47: Held at FY2024 ratio
A48: Accrued salaries % revenue | B48: % | C48: 0.01884 | D48: 0.01884 | E48: 0.01884 | F48: 0.01884 | G48: 0.01884 | H48: Held at FY2024 ratio
...

Sheet Forecast
A1: Integrated three-statement forecast ($ millions)
A2: Independent academic research and valuation case study; not investment advice.
A3: FY2024A links to Historicals; FY2025E-FY2029E are formulas driven by Assumptions. Cash is the only plug; see the balance check.
A5: $ millions | B5: Note | C5: FY2024A | D5: FY2025E | E5: FY2026E | F5: FY2027E | G5: FY2028E | H5: FY2029E
A6: Operating drivers
A7: Warehouses (end of year) | C7: =Historicals!$G$79 -> 890 | D7: =C7+Assumptions!$C$8 -> 916 | E7: =D7+Assumptions!$D$8 -> 943 | F7: =E7+Assumptions!$E$8 -> 970 | G7: =F7+Assumptions!$F$8 -> 997 | H7: =G7+Assumptions!$G$8 -> 1024
A8: Net unit growth | D8: =Assumptions!$C$8/C7 -> 0.029213483 | E8: =Assumptions!$D$8/D7 -> 0.029475983 | F8: =Assumptions!$E$8/E7 -> 0.028632025 | G8: =Assumptions!$F$8/F7 -> 0.027835052 | H8: =Assumptions!$G$8/G7 -> 0.027081244
A9: Comparable sales growth | D9: =Assumptions!$C$13 -> 0.055 | E9: =Assumptions!$D$13 -> 0.05 | F9: =Assumptions!$E$13 -> 0.045 | G9: =Assumptions!$F$13 -> 0.04 | H9: =Assumptions!$G$13 -> 0.04
A10: Growth from new warehouses | D10: =Assumptions!$C$35*D8 -> 0.018988764 | E10: =Assumptions!$D$35*E8 -> 0.019159389 | F10: =Assumptions!$E$35*F8 -> 0.018610817 | G10: =Assumptions!$F$35*G8 -> 0.018092784 | H10: =Assumptions!$G$35*H8 -> 0.017602808
A11: Net sales growth | D11: =(1+D9)*(1+D10)-1 -> 0.075033146 | E11: =(1+E9)*(1+E10)-1 -> 0.070117358 | F11: =(1+F9)*(1+F10)-1 -> 0.064448303 | G11: =(1+G9)*(1+G10)-1 -> 0.058816495 | H11: =(1+H9)*(1+H10)-1 -> 0.058306921
A12: Paid members, end of year (m) | C12: =Historicals!$G$80 -> 76.2 | D12: =C12*(1+Assumptions!$C$18) -> 81.534 | E12: =D12*(1+Assumptions!$D$18) -> 86.83371 | F12: =E12*(1+Assumptions!$E$18) -> 92.043733 | G12: =F12*(1+Assumptions!$F$18) -> 97.106138 | H12: =G12*(1+Assumptions!$G$18) -> 101.96144
A13: Fee increase recognised | D13: =Assumptions!$C$36*Assumptions!$C$37*Assumptions!$C$38 -> 0.0354025 | E13: =Assumptions!$D$36*Assumptions!$D$37*Assumptions!$D$38 -> 0.0354025 | F13: =Assumptions!$E$36*Assumptions!$E$37*Assumptions!$E$38 -> 0 | G13: =Assumptions!$F$36*Assumptions!$F$37*Assumptions!$F$38 -> 0 | H13: =Assumptions!$G$36*Assumptions!$G$37*Assumptions!$G$38 -> 0
A14: Fee income per average paid member ($) | C14: =Historicals!$G$8/AVERAGE(Historicals!$G$80,Historicals!$F$80) -> 65.597826 | D14: =C14*(1+D13)*(1+Assumptions!$C$39) -> 67.920153 | E14: =D14*(1+E13)*(1+Assumptions!$D$39) -> 70.324696 | F14: =E14*(1+F13)*(1+Assumptions!$E$39) -> 70.324696 | G14: =F14*(1+G13)*(1+Assumptions!$F$39) -> 70.324696 | H14: =G14*(1+H13)*(1+Assumptions!$G$39) -> 70.324696
A15: Income statement
A16: Net sales | C16: =Historicals!$G$7 -> 249625 | D16: =C16*(1+D11) -> 268355.15 | E16: =D16*(1+E11) -> 287171.5 | F16: =E16*(1+F11) -> 305679.22 | G16: =F16*(1+G11) -> 323658.2 | H16: =G16*(1+H11) -> 342529.71
A17: Membership fees | C17: =Historicals!$G$8 -> 4828 | D17: =D14*AVERAGE(D12,C12) -> 5356.6587 | E17: =E14*AVERAGE(E12,D12) -> 5920.204 | F17: =F14*AVERAGE(F12,E12) -> 6289.7509 | G17: =G14*AVERAGE(G12,F12) -> 6650.9536 | H17: =H14*AVERAGE(H12,G12) -> 6999.6837
A18: Total revenue | C18: =C16+C17 -> 254453 | D18: =D16+D17 -> 273711.81 | E18: =E16+E17 -> 293091.71 | F18: =F16+F17 -> 311968.97 | G18: =G16+G17 -> 330309.15 | H18: =H16+H17 -> 349529.4
A19: Merchandise costs | C19: =Historicals!$G$10 -> 222358 | D19: =D16*(1-Assumptions!$C$23) -> 238836.08 | E19: =E16*(1-Assumptions!$D$23) -> 255582.64 | F19: =F16*(1-Assumptions!$E$23) -> 272054.51 | G19: =G16*(1-Assumptions!$F$23) -> 288055.8 | H19: =H16*(1-Assumptions!$G$23) -> 304851.44
A20: SG&A | C20: =Historicals!$G$11 -> 22810 | D20: =D16*Assumptions!$C$28 -> 24688.674 | E20: =E16*Assumptions!$D$28 -> 26419.778 | F20: =F16*Assumptions!$E$28 -> 28122.488 | G20: =G16*Assumptions!$F$28 -> 29776.554 | H20: =H16*Assumptions!$G$28 -> 31512.734
A21: Operating income (EBIT) | C21: =C18-C19-C20 -> 9285 | D21: =D18-D19-D20 -> 10187.051 | E21: =E18-E19-E20 -> 11089.291 | F21: =F18-F19-F20 -> 11791.977 | G21: =G18-G19-G20 -> 12476.801 | H21: =H18-H19-H20 -> 13165.218
A22: Interest expense | C22: =Historicals!$G$14 -> 169 | D22: =Assumptions!$C$52 -> 169 | E22: =Assumptions!$D$52 -> 169 | F22: =Assumptions!$E$52 -> 169 | G22: =Assumptions!$F$52 -> 169 | H22: =Assumptions!$G$52 -> 169
A23: Interest income and other | C23: =Historicals!$G$15 -> 624 | D23: =Assumptions!$C$53*(C33+C34) -> 390.04 | E23: =Assumptions!$D$53*(D33+D34) -> 500.3814 | F23: =Assumptions!$E$53*(E33+E34) -> 602.11988 | G23: =Assumptions!$F$53*(F33+F34) -> 750.10416 | H23: =Assumptions!$G$53*(G33+G34) -> 909.68937
A24: Income before taxes | C24: =C21-C22+C23 -> 9740 | D24: =D21-D22+D23 -> 10408.091 | E24: =E21-E22+E23 -> 11420.673 | F24: =F21-F22+F23 -> 12225.097 | G24: =G21-G22+G23 -> 13057.905 | H24: =H21-H22+H23 -> 13905.908
A25: Income taxes | C25: =Historicals!$G$17 -> 2373 | D25: =D24*Assumptions!$C$40 -> 2706.1038 | E25: =E24*Assumptions!$D$40 -> 2969.3749 | F25: =F24*Assumptions!$E$40 -> 3178.5252 | G25: =G24*Assumptions!$F$40 -> 3395.0554 | H25: =H24*Assumptions!$G$40 -> 3615.536
A26: Net income | C26: =Historicals!$G$20 -> 7367 | D26: =D24-D25 -> 7701.9876 | E26: =E24-E25 -> 8451.2977 | F26: =F24-F25 -> 9046.5716 | G26: =G24-G25 -> 9662.85 | H26: =H24-H25 -> 10290.372
A27: Diluted shares (m) | C27: =Historicals!$G$24 -> 444.759 | D27: =Assumptions!$C$57 -> 444.9 | E27: =Assumptions!$D$57 -> 444.9 | F27: =Assumptions!$E$57 -> 444.9 | G27: =Assumptions!$F$57 -> 444.9 | H27: =Assumptions!$G$57 -> 444.9
A28: Diluted EPS ($) | C28: =Historicals!$G$22 -> 16.56 | D28: =D26/D27 -> 17.311728 | E28: =E26/E27 -> 18.995949 | F28: =F26/F27 -> 20.333944 | G28: =G26/G27 -> 21.71915 | H28: =H26/H27 -> 23.129629
A29: Depreciation & amortisation | C29: =Historicals!$G$56 -> 2237 | D29: =Assumptions!$C$41*C38 -> 2438.688 | E29: =Assumptions!$D$41*D38 -> 2653.8382 | F29: =Assumptions!$E$41*E38 -> 2886.3803 | G29: =Assumptions!$F$41*F38 -> 3128.7241 | H29: =Assumptions!$G$41*G38 -> 3379.2117
A30: EBITDA | C30: =C21+C29 -> 11522 | D30: =D21+D29 -> 12625.739 | E30: =E21+E29 -> 13743.129 | F30: =F21+F29 -> 14678.357 | G30: =G21+G29 -> 15605.525 | H30: =H21+H29 -> 16544.43
A31: Operating margin | C31: =C21/C18 -> 0.036490039 | D31: =D21/D18 -> 0.037218166 | E31: =E21/E18 -> 0.037835568 | F31: =F21/F18 -> 0.037798557 | G31: =G21/G18 -> 0.037773102 | H31: =H21/H18 -> 0.037665554
A32: Balance sheet
A33: Cash and cash equivalents | C33: =Historicals!$G$27 -> 9906 | D33: =C33+D67 -> 14158.351 | E33: =D33+E67 -> 18832.663 | F33: =E33+F67 -> 23765.472 | G33: =F33+G67 -> 29084.979 | H33: =G33+H67 -> 34846.293
A34: Short-term investments | C34: =Historicals!$G$28 -> 1238 | D34: =C34 -> 1238 | E34: =D34 -> 1238 | F34: =E34 -> 1238 | G34: =F34 -> 1238 | H34: =G34 -> 1238
A35: Receivables | C35: =Historicals!$G$29 -> 2721 | D35: =Assumptions!$C$44*D18 -> 2925.9792 | E35: =Assumptions!$D$44*E18 -> 3133.1504 | F35: =Assumptions!$E$44*F18 -> 3334.9483 | G35: =Assumptions!$F$44*G18 -> 3531.0048 | H35: =Assumptions!$G$44*H18 -> 3736.4692
A36: Merchandise inventories | C36: =Historicals!$G$30 -> 18647 | D36: =Assumptions!$C$45*D18 -> 20057.601 | E36: =Assumptions!$D$45*E18 -> 21477.76 | F36: =Assumptions!$E$45*F18 -> 22861.086 | G36: =Assumptions!$F$45*G18 -> 24205.055 | H36: =Assumptions!$G$45*H18 -> 25613.514
A37: Other current assets | C37: =Historicals!$G$31 -> 1734 | D37: =Assumptions!$C$46*D18 -> 1863.9774 | E37: =Assumptions!$D$46*E18 -> 1995.9545 | F37: =Assumptions!$E$46*F18 -> 2124.5087 | G37: =Assumptions!$F$46*G18 -> 2249.4053 | H37: =Assumptions!$G$46*H18 -> 2380.2952
A38: Property and equipment, net | C38: =Historicals!$G$33 -> 29032 | D38: =C38+D62-D29 -> 31593.312 | E38: =D38+E62-E29 -> 34361.67 | F38: =E38+F62-F29 -> 37246.716 | G38: =F38+G62-G29 -> 40228.711 | H38: =G38+H62-H29 -> 43315.793
A39: Operating lease ROU assets | C39: =Historicals!$G$34 -> 2617 | D39: =C39 -> 2617 | E39: =D39 -> 2617 | F39: =E39 -> 2617 | G39: =F39 -> 2617 | H39: =G39 -> 2617
A40: Other long-term assets | C40: =Historicals!$G$35 -> 3936 | D40: =C40 -> 3936 | E40: =D40 -> 3936 | F40: =E40 -> 3936 | G40: =F40 -> 3936 | H40: =G40 -> 3936
A41: Total assets | C41: =SUM(C33:C40) -> 69831 | D41: =SUM(D33:D40) -> 78390.221 | E41: =SUM(E33:E40) -> 87592.198 | F41: =SUM(F33:F40) -> 97123.731 | G41: =SUM(G33:G40) -> 107090.16 | H41: =SUM(H33:H40) -> 117683.37
...

Sheet Beta
A1: Beta regression: Costco vs. S&P 500, 60 monthly total returns (Feb 2020 - Jan 2025)
A2: Independent academic research and valuation case study; not investment advice.
A3: Source: Yahoo Finance dividend/split-adjusted monthly closes (data/raw/market/yahoo_*_monthly.csv).
A5: Month | B5: COST adj. close | C5: S&P 500 close | D5: COST return | E5: S&P 500 return | G5: Regression
A6: Jan 2020 | B6: 278.0972 | C6: 3225.52 | G6: Raw beta (SLOPE) | H6: =SLOPE(D7:D66,E7:E66) -> 0.84262569
A7: Feb 2020 | B7: 256.445 | C7: 2954.22 | D7: =B7/B6-1 -> -0.077858389 | E7: =C7/C6-1 -> -0.084110469 | G7: R-squared (RSQ) | H7: =RSQ(D7:D66,E7:E66) -> 0.44288631
A8: Mar 2020 | B8: 260.0845 | C8: 2584.5901 | D8: =B8/B7-1 -> 0.014192127 | E8: =C8/C7-1 -> -0.12511929 | G8: Observations | H8: =COUNT(D7:D66) -> 60
A9: Apr 2020 | B9: 277.0163 | C9: 2912.4299 | D9: =B9/B8-1 -> 0.06510115 | E9: =C9/C8-1 -> 0.12684402
A10: May 2020 | B10: 282.0172 | C10: 3044.3101 | D10: =B10/B9-1 -> 0.018052728 | E10: =C10/C9-1 -> 0.045281845
A11: Jun 2020 | B11: 277.2083 | C11: 3100.29 | D11: =B11/B10-1 -> -0.017051797 | E11: =C11/C10-1 -> 0.01838837
A12: Jul 2020 | B12: 298.2544 | C12: 3271.1201 | D12: =B12/B11-1 -> 0.075921608 | E12: =C12/C11-1 -> 0.055101329
A13: Aug 2020 | B13: 318.5302 | C13: 3500.3101 | D13: =B13/B12-1 -> 0.067981562 | E13: =C13/C12-1 -> 0.070064685
A14: Sep 2020 | B14: 325.2552 | C14: 3363 | D14: =B14/B13-1 -> 0.021112598 | E14: =C14/C13-1 -> -0.039227982
A15: Oct 2020 | B15: 328.2854 | C15: 3269.96 | D15: =B15/B14-1 -> 0.0093163768 | E15: =C15/C14-1 -> -0.027665775
A16: Nov 2020 | B16: 359.6341 | C16: 3621.6299 | D16: =B16/B15-1 -> 0.095492215 | E16: =C16/C15-1 -> 0.10754563
A17: Dec 2020 | B17: 354.9334 | C17: 3756.0701 | D17: =B17/B16-1 -> -0.013070785 | E17: =C17/C16-1 -> 0.037121463
A18: Jan 2021 | B18: 331.9952 | C18: 3714.24 | D18: =B18/B17-1 -> -0.064626772 | E18: =C18/C17-1 -> -0.011136666
A19: Feb 2021 | B19: 312.4235 | C19: 3811.1499 | D19: =B19/B18-1 -> -0.058951756 | E19: =C19/C18-1 -> 0.026091448
A20: Mar 2021 | B20: 332.698 | C20: 3972.8899 | D20: =B20/B19-1 -> 0.064894286 | E20: =C20/C19-1 -> 0.042438635
... A66: Jan 2025 | B66: 970.5099 | C66: 6040.5298 | D66: =B66/B65-1 -> 0.069422734 | E66: =C66/C65-1 -> 0.027016304

Sheet WACC
A1: Weighted average cost of capital, 31 Jan 2025
A2: Independent academic research and valuation case study; not investment advice.
A3: WACC = E/(D+E) x Re + D/(D+E) x Rd x (1 - T); Re = Rf + beta x ERP
A5: Item | B5: Value | C5: Source / note
A6: Risk-free rate (10-year Treasury, 31 Jan 2025) | B6: 0.0458 | C6: FRED DGS10 = 4.58% on 31 Jan 2025 (data/raw/market/fred_DGS10.csv)
A7: Equity risk premium | B7: 0.0433 | C7: Damodaran implied ERP (FCFE), start of 2025 = 4.33% (histimpl.xls)
A8: Raw beta | B8: =Beta!$H$6 -> 0.84262569 | C8: Beta sheet: SLOPE of 60 monthly returns
A9: Blume weight on raw beta | B9: 0.67 | C9: Adjusted beta = 0.67 x raw + 0.33 x 1.0
A10: Adjusted beta | B10: =B9*B8+(1-B9) -> 0.89455921
A11: Cost of equity | B11: =B6+B10*B7 -> 0.084534414
A12: ICE BofA AA corporate OAS | B12: 0.0046 | C12: FRED BAMLC0A2CAA, 31 Jan 2025
A13: ICE BofA A corporate OAS | B13: 0.0069 | C13: FRED BAMLC0A3CA, 31 Jan 2025
A14: Pre-tax cost of debt | B14: =B6+AVERAGE(B12,B13) -> 0.05155
A15: Tax rate | B15: =Assumptions!$C$40 -> 0.26
A16: After-tax cost of debt | B16: =B14*(1-B15) -> 0.038147
A17: Share price, 31 Jan 2025 ($) | B17: 979.88 | C17: Yahoo Finance close, 31 Jan 2025
A18: Basic shares outstanding (m) | B18: 443.89887 | C18: 10-Q cover page, shares outstanding at 2024-12-11
A19: RSU dilution (m) | B19: 0.903 | C19: Q1 FY2025 diluted less basic weighted shares (treasury-stock method)
A20: Diluted shares (m) | B20: =B18+B19 -> 444.80187
A21: Equity market value ($m) | B21: =B17*B20 -> 435852.46
A22: Fair value of long-term debt ($m) | B22: 5273 | C22: Q1 FY2025 10-Q: fair value of long-term debt incl. current portion
A23: Finance lease liabilities ($m) | B23: 1498 | C23: FY2024 10-K lease note: total lease liabilities 4,052 less operating 2,554
A24: Debt incl. finance leases ($m) | B24: =B22+B23 -> 6771
A25: Weight of equity | B25: =B21/(B21+B24) -> 0.98470257
A26: Weight of debt | B26: =B24/(B21+B24) -> 0.015297427
A27: WACC | B27: =B25*B11+B26*B16 -> 0.083824806

Sheet DCF
A1: Discounted cash flow valuation, 31 Jan 2025 ($ millions)
A2: Independent academic research and valuation case study; not investment advice.
A3: UFCF = EBIT x (1 - T) + D&A - capex - increase in working capital. Mid-year convention; FY2025 is a stub from the 24 Nov 2024 balance sheet.
A5: Valuation date | B5: 45688
A6: Balance-sheet date (Q1 FY2025 10-Q) | B6: 45620
A7: FY2025 start | B7: 45537
A8: WACC | B8: =WACC!$B$27 -> 0.083824806
A9: Terminal growth (g) | B9: =Assumptions!$C$60 -> 0.03
A10: Terminal RONIC | B10: =Assumptions!$C$61 -> 0.25
A11: Tax rate | B11: =WACC!$B$15 -> 0.26
A13: $ millions | C13: FY2025E | D13: FY2026E | E13: FY2027E | F13: FY2028E | G13: FY2029E
A14: Fiscal year end | C14: 45900 | D14: 46264 | E14: 46628 | F14: 46999 | G14: 47363
A15: EBIT | C15: =Forecast!D21 -> 10187.051 | D15: =Forecast!E21 -> 11089.291 | E15: =Forecast!F21 -> 11791.977 | F15: =Forecast!G21 -> 12476.801 | G15: =Forecast!H21 -> 13165.218
A16: Taxes on EBIT | C16: =C15*$B$11 -> 2648.6334 | D16: =D15*$B$11 -> 2883.2157 | E16: =E15*$B$11 -> 3065.914 | F16: =F15*$B$11 -> 3243.9683 | G16: =G15*$B$11 -> 3422.9568
A17: NOPAT | C17: =C15-C16 -> 7538.418 | D17: =D15-D16 -> 8206.0754 | E17: =E15-E16 -> 8726.0629 | F17: =F15-F16 -> 9232.8329 | G17: =G15-G16 -> 9742.2617
A18: + D&A | C18: =Forecast!D29 -> 2438.688 | D18: =Forecast!E29 -> 2653.8382 | E18: =Forecast!F29 -> 2886.3803 | F18: =Forecast!G29 -> 3128.7241 | G18: =Forecast!H29 -> 3379.2117
A19: - Capex | C19: =Forecast!D62 -> 5000 | D19: =Forecast!E62 -> 5422.1966 | E19: =Forecast!F62 -> 5771.4259 | F19: =Forecast!G62 -> 6110.7193 | G19: =Forecast!H62 -> 6466.2938
A20: + Working capital released | C20: =Forecast!D60 -> 1015.3342 | D20: =Forecast!E60 -> 1035.3294 | E20: =Forecast!F60 -> 915.55709 | F20: =Forecast!G60 -> 890.63241 | G20: =Forecast!H60 -> 917.93069
A21: Unlevered free cash flow | C21: =C17+C18-C19+C20 -> 5992.4402 | D21: =D17+D18-D19+D20 -> 6473.0465 | E21: =E17+E18-E19+E20 -> 6756.5743 | F21: =F17+F18-F19+F20 -> 7141.4701 | G21: =G17+G18-G19+G20 -> 7573.1103
A22: Share of year counted | C22: =(C14-$B$6)/(C14-$B$7+1) -> 0.76923077 | D22: 1 | E22: 1 | F22: 1 | G22: 1
A23: Period start | C23: =$B$6 -> 45620 | D23: =C14 -> 45900 | E23: =D14 -> 46264 | F23: =E14 -> 46628 | G23: =F14 -> 46999
A24: Period midpoint | C24: =C23+INT((C14-C23)/2) -> 45760 | D24: =D23+INT((D14-D23)/2) -> 46082 | E24: =E23+INT((E14-E23)/2) -> 46446 | F24: =F23+INT((F14-F23)/2) -> 46813 | G24: =G23+INT((G14-G23)/2) -> 47181
A25: Discount time (years from valuation date) | C25: =MAX((C24-$B$5)/365.25,0) -> 0.19712526 | D25: =MAX((D24-$B$5)/365.25,0) -> 1.0787132 | E25: =MAX((E24-$B$5)/365.25,0) -> 2.0752909 | F25: =MAX((F24-$B$5)/365.25,0) -> 3.0800821 | G25: =MAX((G24-$B$5)/365.25,0) -> 4.0876112
A26: UFCF in period | C26: =C21*C22 -> 4609.5694 | D26: =D21*D22 -> 6473.0465 | E26: =E21*E22 -> 6756.5743 | F26: =F21*F22 -> 7141.4701 | G26: =G21*G22 -> 7573.1103
A27: Discount factor | C27: =1/(1+$B$8)^C25 -> 0.98425738 | D27: =1/(1+$B$8)^D25 -> 0.91683075 | E27: =1/(1+$B$8)^E25 -> 0.84615461 | F27: =1/(1+$B$8)^F25 -> 0.78041057 | G27: =1/(1+$B$8)^G25 -> 0.71961606
A28: PV of UFCF | C28: =C26*C27 -> 4537.0027 | D28: =D26*D27 -> 5934.688 | E28: =E26*E27 -> 5717.1065 | F28: =F26*F27 -> 5573.2787 | G28: =G26*G27 -> 5449.7318
A29: EBITDA | C29: =Forecast!D30 -> 12625.739 | D29: =Forecast!E30 -> 13743.129 | E29: =Forecast!F30 -> 14678.357 | F29: =Forecast!G30 -> 15605.525 | G29: =Forecast!H30 -> 16544.43
A31: Terminal value
A32: NOPAT FY2030 = EBIT FY2029 x (1 + g) x (1 - T) | B32: =G15*(1+$B$9)*(1-$B$11) -> 10034.53
A33: Reinvestment rate = g / RONIC | B33: =$B$9/$B$10 -> 0.12
A34: Terminal FCF FY2030 | B34: =B32*(1-B33) -> 8830.386
A35: Terminal value = FCF / (WACC - g) | B35: =B34/($B$8-$B$9) -> 164057.93
A36: PV of terminal value (discounted consistently with mid-year flows) | B36: =B35/(1+$B$8)^G25 -> 118058.72
A37: Enterprise value to equity value
A38: Sum of PV of UFCF | B38: =SUM(C28:G28) -> 27211.808
A39: PV of terminal value | B39: =B36 -> 118058.72
A40: Enterprise value | B40: =B38+B39 -> 145270.53
A41: Terminal value % of EV | B41: =B39/B40 -> 0.81268184
A42: + Cash and cash equivalents (24 Nov 2024) | B42: 10907 | C42: Q1 FY2025 10-Q balance sheet
A43: + Short-term investments | B43: 920 | C43: Q1 FY2025 10-Q balance sheet
...

Sheet Sensitivity
A1: Sensitivity analysis: DCF value per share ($)
A2: Independent academic research and valuation case study; not investment advice.
A3: Grids 1-2 are live formulas that recompute the DCF for each cell. Grid 3 needs the forecast re-run per cell, so it is pasted from src/sensitivity.py.
A5: Row and column headers in blue are editable; WACC rows are centred on the live WACC. Yellow = base case.
A7: 1. WACC x terminal growth
A8: WACC (rows) x terminal growth (columns); RONIC held at base
B9: 0.02 | C9: 0.025 | D9: 0.03 | E9: 0.035 | F9: 0.04
A10: =DCF!$B$8-0.01 -> 0.073824806 | B10: =(SUMPRODUCT(DCF!$C$26:$G$26,(1+$A10)^(-DCF!$C$25:$G$25))+DCF!$G$15*(1+B$9)*(1-DCF!$B$11)*(1-B$9/DCF!$B$10)/($A10-B$9)/(1+$A10)^DCF!$G$25+DCF!$B$52)/DCF!$B$47 -> 357.904 | C10: =(SUMPRODUCT(DCF!$C$26:$G$26,(1+$A10)^(-DCF!$C$25:$G$25))+DCF!$G$15*(1+C$9)*(1-DCF!$B$11)*(1-C$9/DCF!$B$10)/($A10-C$9)/(1+$A10)^DCF!$G$25+DCF!$B$52)/DCF!$B$47 -> 381.80004 | D10: =(SUMPRODUCT(DCF!$C$26:$G$26,(1+$A10)^(-DCF!$C$25:$G$25))+DCF!$G$15*(1+D$9)*(1-DCF!$B$11)*(1-D$9/DCF!$B$10)/($A10-D$9)/(1+$A10)^DCF!$G$25+DCF!$B$52)/DCF!$B$47 -> 411.074 | E10: =(SUMPRODUCT(DCF!$C$26:$G$26,(1+$A10)^(-DCF!$C$25:$G$25))+DCF!$G$15*(1+E$9)*(1-DCF!$B$11)*(1-E$9/DCF!$B$10)/($A10-E$9)/(1+$A10)^DCF!$G$25+DCF!$B$52)/DCF!$B$47 -> 447.80365 | F10: =(SUMPRODUCT(DCF!$C$26:$G$26,(1+$A10)^(-DCF!$C$25:$G$25))+DCF!$G$15*(1+F$9)*(1-DCF!$B$11)*(1-F$9/DCF!$B$10)/($A10-F$9)/(1+$A10)^DCF!$G$25+DCF!$B$52)/DCF!$B$47 -> 495.2953
A11: =DCF!$B$8-0.005 -> 0.078824806 | B11: =(SUMPRODUCT(DCF!$C$26:$G$26,(1+$A11)^(-DCF!$C$25:$G$25))+DCF!$G$15*(1+B$9)*(1-DCF!$B$11)*(1-B$9/DCF!$B$10)/($A11-B$9)/(1+$A11)^DCF!$G$25+DCF!$B$52)/DCF!$B$47 -> 328.10855 | C11: =(SUMPRODUCT(DCF!$C$26:$G$26,(1+$A11)^(-DCF!$C$25:$G$25))+DCF!$G$15*(1+C$9)*(1-DCF!$B$11)*(1-C$9/DCF!$B$10)/($A11-C$9)/(1+$A11)^DCF!$G$25+DCF!$B$52)/DCF!$B$47 -> 347.16598 | D11: =(SUMPRODUCT(DCF!$C$26:$G$26,(1+$A11)^(-DCF!$C$25:$G$25))+DCF!$G$15*(1+D$9)*(1-DCF!$B$11)*(1-D$9/DCF!$B$10)/($A11-D$9)/(1+$A11)^DCF!$G$25+DCF!$B$52)/DCF!$B$47 -> 370.06085 | E11: =(SUMPRODUCT(DCF!$C$26:$G$26,(1+$A11)^(-DCF!$C$25:$G$25))+DCF!$G$15*(1+E$9)*(1-DCF!$B$11)*(1-E$9/DCF!$B$10)/($A11-E$9)/(1+$A11)^DCF!$G$25+DCF!$B$52)/DCF!$B$47 -> 398.1066 | F11: =(SUMPRODUCT(DCF!$C$26:$G$26,(1+$A11)^(-DCF!$C$25:$G$25))+DCF!$G$15*(1+F$9)*(1-DCF!$B$11)*(1-F$9/DCF!$B$10)/($A11-F$9)/(1+$A11)^DCF!$G$25+DCF!$B$52)/DCF!$B$47 -> 433.29328
A12: =DCF!$B$8 -> 0.083824806 | B12: =(SUMPRODUCT(DCF!$C$26:$G$26,(1+$A12)^(-DCF!$C$25:$G$25))+DCF!$G$15*(1+B$9)*(1-DCF!$B$11)*(1-B$9/DCF!$B$10)/($A12-B$9)/(1+$A12)^DCF!$G$25+DCF!$B$52)/DCF!$B$47 -> 303.00048 | C12: =(SUMPRODUCT(DCF!$C$26:$G$26,(1+$A12)^(-DCF!$C$25:$G$25))+DCF!$G$15*(1+C$9)*(1-DCF!$B$11)*(1-C$9/DCF!$B$10)/($A12-C$9)/(1+$A12)^DCF!$G$25+DCF!$B$52)/DCF!$B$47 -> 318.43737 | D12: =(SUMPRODUCT(DCF!$C$26:$G$26,(1+$A12)^(-DCF!$C$25:$G$25))+DCF!$G$15*(1+D$9)*(1-DCF!$B$11)*(1-D$9/DCF!$B$10)/($A12-D$9)/(1+$A12)^DCF!$G$25+DCF!$B$52)/DCF!$B$47 -> 336.68367 | E12: =(SUMPRODUCT(DCF!$C$26:$G$26,(1+$A12)^(-DCF!$C$25:$G$25))+DCF!$G$15*(1+E$9)*(1-DCF!$B$11)*(1-E$9/DCF!$B$10)/($A12-E$9)/(1+$A12)^DCF!$G$25+DCF!$B$52)/DCF!$B$47 -> 358.6025 | F12: =(SUMPRODUCT(DCF!$C$26:$G$26,(1+$A12)^(-DCF!$C$25:$G$25))+DCF!$G$15*(1+F$9)*(1-DCF!$B$11)*(1-F$9/DCF!$B$10)/($A12-F$9)/(1+$A12)^DCF!$G$25+DCF!$B$52)/DCF!$B$47 -> 385.45088
A13: =DCF!$B$8+0.005 -> 0.088824806 | B13: =(SUMPRODUCT(DCF!$C$26:$G$26,(1+$A13)^(-DCF!$C$25:$G$25))+DCF!$G$15*(1+B$9)*(1-DCF!$B$11)*(1-B$9/DCF!$B$10)/($A13-B$9)/(1+$A13)^DCF!$G$25+DCF!$B$52)/DCF!$B$47 -> 281.55773 | C13: =(SUMPRODUCT(DCF!$C$26:$G$26,(1+$A13)^(-DCF!$C$25:$G$25))+DCF!$G$15*(1+C$9)*(1-DCF!$B$11)*(1-C$9/DCF!$B$10)/($A13-C$9)/(1+$A13)^DCF!$G$25+DCF!$B$52)/DCF!$B$47 -> 294.22584 | D13: =(SUMPRODUCT(DCF!$C$26:$G$26,(1+$A13)^(-DCF!$C$25:$G$25))+DCF!$G$15*(1+D$9)*(1-DCF!$B$11)*(1-D$9/DCF!$B$10)/($A13-D$9)/(1+$A13)^DCF!$G$25+DCF!$B$52)/DCF!$B$47 -> 308.9949 | E13: =(SUMPRODUCT(DCF!$C$26:$G$26,(1+$A13)^(-DCF!$C$25:$G$25))+DCF!$G$15*(1+E$9)*(1-DCF!$B$11)*(1-E$9/DCF!$B$10)/($A13-E$9)/(1+$A13)^DCF!$G$25+DCF!$B$52)/DCF!$B$47 -> 326.45039 | F13: =(SUMPRODUCT(DCF!$C$26:$G$26,(1+$A13)^(-DCF!$C$25:$G$25))+DCF!$G$15*(1+F$9)*(1-DCF!$B$11)*(1-F$9/DCF!$B$10)/($A13-F$9)/(1+$A13)^DCF!$G$25+DCF!$B$52)/DCF!$B$47 -> 347.41766
A14: =DCF!$B$8+0.01 -> 0.093824806 | B14: =(SUMPRODUCT(DCF!$C$26:$G$26,(1+$A14)^(-DCF!$C$25:$G$25))+DCF!$G$15*(1+B$9)*(1-DCF!$B$11)*(1-B$9/DCF!$B$10)/($A14-B$9)/(1+$A14)^DCF!$G$25+DCF!$B$52)/DCF!$B$47 -> 263.03511 | C14: =(SUMPRODUCT(DCF!$C$26:$G$26,(1+$A14)^(-DCF!$C$25:$G$25))+DCF!$G$15*(1+C$9)*(1-DCF!$B$11)*(1-C$9/DCF!$B$10)/($A14-C$9)/(1+$A14)^DCF!$G$25+DCF!$B$52)/DCF!$B$47 -> 273.54653 | D14: =(SUMPRODUCT(DCF!$C$26:$G$26,(1+$A14)^(-DCF!$C$25:$G$25))+DCF!$G$15*(1+D$9)*(1-DCF!$B$11)*(1-D$9/DCF!$B$10)/($A14-D$9)/(1+$A14)^DCF!$G$25+DCF!$B$52)/DCF!$B$47 -> 285.65729 | E14: =(SUMPRODUCT(DCF!$C$26:$G$26,(1+$A14)^(-DCF!$C$25:$G$25))+DCF!$G$15*(1+E$9)*(1-DCF!$B$11)*(1-E$9/DCF!$B$10)/($A14-E$9)/(1+$A14)^DCF!$G$25+DCF!$B$52)/DCF!$B$47 -> 299.77523 | F14: =(SUMPRODUCT(DCF!$C$26:$G$26,(1+$A14)^(-DCF!$C$25:$G$25))+DCF!$G$15*(1+F$9)*(1-DCF!$B$11)*(1-F$9/DCF!$B$10)/($A14-F$9)/(1+$A14)^DCF!$G$25+DCF!$B$52)/DCF!$B$47 -> 316.4597
A16: 2. Terminal RONIC x terminal growth (terminal-year cash flow)
A17: RONIC (rows) x terminal growth (columns); WACC held at base
B18: 0.02 | C18: 0.025 | D18: 0.03 | E18: 0.035 | F18: 0.04
A19: 0.15 | B19: =(SUMPRODUCT(DCF!$C$26:$G$26,(1+DCF!$B$8)^(-DCF!$C$25:$G$25))+DCF!$G$15*(1+B$18)*(1-DCF!$B$11)*(1-B$18/$A19)/(DCF!$B$8-B$18)/(1+DCF!$B$8)^DCF!$G$25+DCF!$B$52)/DCF!$B$47 -> 289.56654 | C19: =(SUMPRODUCT(DCF!$C$26:$G$26,(1+DCF!$B$8)^(-DCF!$C$25:$G$25))+DCF!$G$15*(1+C$18)*(1-DCF!$B$11)*(1-C$18/$A19)/(DCF!$B$8-C$18)/(1+DCF!$B$8)^DCF!$G$25+DCF!$B$52)/DCF!$B$47 -> 300.1283 | D19: =(SUMPRODUCT(DCF!$C$26:$G$26,(1+DCF!$B$8)^(-DCF!$C$25:$G$25))+DCF!$G$15*(1+D$18)*(1-DCF!$B$11)*(1-D$18/$A19)/(DCF!$B$8-D$18)/(1+DCF!$B$8)^DCF!$G$25+DCF!$B$52)/DCF!$B$47 -> 312.5547 | E19: =(SUMPRODUCT(DCF!$C$26:$G$26,(1+DCF!$B$8)^(-DCF!$C$25:$G$25))+DCF!$G$15*(1+E$18)*(1-DCF!$B$11)*(1-E$18/$A19)/(DCF!$B$8-E$18)/(1+DCF!$B$8)^DCF!$G$25+DCF!$B$52)/DCF!$B$47 -> 327.41859 | F19: =(SUMPRODUCT(DCF!$C$26:$G$26,(1+DCF!$B$8)^(-DCF!$C$25:$G$25))+DCF!$G$15*(1+F$18)*(1-DCF!$B$11)*(1-F$18/$A19)/(DCF!$B$8-F$18)/(1+DCF!$B$8)^DCF!$G$25+DCF!$B$52)/DCF!$B$47 -> 345.55426
A20: 0.2 | B20: =(SUMPRODUCT(DCF!$C$26:$G$26,(1+DCF!$B$8)^(-DCF!$C$25:$G$25))+DCF!$G$15*(1+B$18)*(1-DCF!$B$11)*(1-B$18/$A20)/(DCF!$B$8-B$18)/(1+DCF!$B$8)^DCF!$G$25+DCF!$B$52)/DCF!$B$47 -> 297.96276 | C20: =(SUMPRODUCT(DCF!$C$26:$G$26,(1+DCF!$B$8)^(-DCF!$C$25:$G$25))+DCF!$G$15*(1+C$18)*(1-DCF!$B$11)*(1-C$18/$A20)/(DCF!$B$8-C$18)/(1+DCF!$B$8)^DCF!$G$25+DCF!$B$52)/DCF!$B$47 -> 311.57147 | D20: =(SUMPRODUCT(DCF!$C$26:$G$26,(1+DCF!$B$8)^(-DCF!$C$25:$G$25))+DCF!$G$15*(1+D$18)*(1-DCF!$B$11)*(1-D$18/$A20)/(DCF!$B$8-D$18)/(1+DCF!$B$8)^DCF!$G$25+DCF!$B$52)/DCF!$B$47 -> 327.6353 | E20: =(SUMPRODUCT(DCF!$C$26:$G$26,(1+DCF!$B$8)^(-DCF!$C$25:$G$25))+DCF!$G$15*(1+E$18)*(1-DCF!$B$11)*(1-E$18/$A20)/(DCF!$B$8-E$18)/(1+DCF!$B$8)^DCF!$G$25+DCF!$B$52)/DCF!$B$47 -> 346.90854 | F20: =(SUMPRODUCT(DCF!$C$26:$G$26,(1+DCF!$B$8)^(-DCF!$C$25:$G$25))+DCF!$G$15*(1+F$18)*(1-DCF!$B$11)*(1-F$18/$A20)/(DCF!$B$8-F$18)/(1+DCF!$B$8)^DCF!$G$25+DCF!$B$52)/DCF!$B$47 -> 370.48965
A21: 0.25 | B21: =(SUMPRODUCT(DCF!$C$26:$G$26,(1+DCF!$B$8)^(-DCF!$C$25:$G$25))+DCF!$G$15*(1+B$18)*(1-DCF!$B$11)*(1-B$18/$A21)/(DCF!$B$8-B$18)/(1+DCF!$B$8)^DCF!$G$25+DCF!$B$52)/DCF!$B$47 -> 303.00048 | C21: =(SUMPRODUCT(DCF!$C$26:$G$26,(1+DCF!$B$8)^(-DCF!$C$25:$G$25))+DCF!$G$15*(1+C$18)*(1-DCF!$B$11)*(1-C$18/$A21)/(DCF!$B$8-C$18)/(1+DCF!$B$8)^DCF!$G$25+DCF!$B$52)/DCF!$B$47 -> 318.43737 | D21: =(SUMPRODUCT(DCF!$C$26:$G$26,(1+DCF!$B$8)^(-DCF!$C$25:$G$25))+DCF!$G$15*(1+D$18)*(1-DCF!$B$11)*(1-D$18/$A21)/(DCF!$B$8-D$18)/(1+DCF!$B$8)^DCF!$G$25+DCF!$B$52)/DCF!$B$47 -> 336.68367 | E21: =(SUMPRODUCT(DCF!$C$26:$G$26,(1+DCF!$B$8)^(-DCF!$C$25:$G$25))+DCF!$G$15*(1+E$18)*(1-DCF!$B$11)*(1-E$18/$A21)/(DCF!$B$8-E$18)/(1+DCF!$B$8)^DCF!$G$25+DCF!$B$52)/DCF!$B$47 -> 358.6025 | F21: =(SUMPRODUCT(DCF!$C$26:$G$26,(1+DCF!$B$8)^(-DCF!$C$25:$G$25))+DCF!$G$15*(1+F$18)*(1-DCF!$B$11)*(1-F$18/$A21)/(DCF!$B$8-F$18)/(1+DCF!$B$8)^DCF!$G$25+DCF!$B$52)/DCF!$B$47 -> 385.45088
A22: 0.3 | B22: =(SUMPRODUCT(DCF!$C$26:$G$26,(1+DCF!$B$8)^(-DCF!$C$25:$G$25))+DCF!$G$15*(1+B$18)*(1-DCF!$B$11)*(1-B$18/$A22)/(DCF!$B$8-B$18)/(1+DCF!$B$8)^DCF!$G$25+DCF!$B$52)/DCF!$B$47 -> 306.35897 | C22: =(SUMPRODUCT(DCF!$C$26:$G$26,(1+DCF!$B$8)^(-DCF!$C$25:$G$25))+DCF!$G$15*(1+C$18)*(1-DCF!$B$11)*(1-C$18/$A22)/(DCF!$B$8-C$18)/(1+DCF!$B$8)^DCF!$G$25+DCF!$B$52)/DCF!$B$47 -> 323.01463 | D22: =(SUMPRODUCT(DCF!$C$26:$G$26,(1+DCF!$B$8)^(-DCF!$C$25:$G$25))+DCF!$G$15*(1+D$18)*(1-DCF!$B$11)*(1-D$18/$A22)/(DCF!$B$8-D$18)/(1+DCF!$B$8)^DCF!$G$25+DCF!$B$52)/DCF!$B$47 -> 342.71591 | E22: =(SUMPRODUCT(DCF!$C$26:$G$26,(1+DCF!$B$8)^(-DCF!$C$25:$G$25))+DCF!$G$15*(1+E$18)*(1-DCF!$B$11)*(1-E$18/$A22)/(DCF!$B$8-E$18)/(1+DCF!$B$8)^DCF!$G$25+DCF!$B$52)/DCF!$B$47 -> 366.39848 | F22: =(SUMPRODUCT(DCF!$C$26:$G$26,(1+DCF!$B$8)^(-DCF!$C$25:$G$25))+DCF!$G$15*(1+F$18)*(1-DCF!$B$11)*(1-F$18/$A22)/(DCF!$B$8-F$18)/(1+DCF!$B$8)^DCF!$G$25+DCF!$B$52)/DCF!$B$47 -> 395.42503
A23: 0.35 | B23: =(SUMPRODUCT(DCF!$C$26:$G$26,(1+DCF!$B$8)^(-DCF!$C$25:$G$25))+DCF!$G$15*(1+B$18)*(1-DCF!$B$11)*(1-B$18/$A23)/(DCF!$B$8-B$18)/(1+DCF!$B$8)^DCF!$G$25+DCF!$B$52)/DCF!$B$47 -> 308.75789 | C23: =(SUMPRODUCT(DCF!$C$26:$G$26,(1+DCF!$B$8)^(-DCF!$C$25:$G$25))+DCF!$G$15*(1+C$18)*(1-DCF!$B$11)*(1-C$18/$A23)/(DCF!$B$8-C$18)/(1+DCF!$B$8)^DCF!$G$25+DCF!$B$52)/DCF!$B$47 -> 326.28411 | D23: =(SUMPRODUCT(DCF!$C$26:$G$26,(1+DCF!$B$8)^(-DCF!$C$25:$G$25))+DCF!$G$15*(1+D$18)*(1-DCF!$B$11)*(1-D$18/$A23)/(DCF!$B$8-D$18)/(1+DCF!$B$8)^DCF!$G$25+DCF!$B$52)/DCF!$B$47 -> 347.02465 | E23: =(SUMPRODUCT(DCF!$C$26:$G$26,(1+DCF!$B$8)^(-DCF!$C$25:$G$25))+DCF!$G$15*(1+E$18)*(1-DCF!$B$11)*(1-E$18/$A23)/(DCF!$B$8-E$18)/(1+DCF!$B$8)^DCF!$G$25+DCF!$B$52)/DCF!$B$47 -> 371.96704 | F23: =(SUMPRODUCT(DCF!$C$26:$G$26,(1+DCF!$B$8)^(-DCF!$C$25:$G$25))+DCF!$G$15*(1+F$18)*(1-DCF!$B$11)*(1-F$18/$A23)/(DCF!$B$8-F$18)/(1+DCF!$B$8)^DCF!$G$25+DCF!$B$52)/DCF!$B$47 -> 402.54943
A25: 3. Comparable-sales growth x gross margin (static values from src/sensitivity.py)
A26: Each cell re-runs the full three-statement forecast, which a formula grid cannot do; re-run python -m src.sensitivity to refresh.
B27: GM -30bp | C27: GM -15bp | D27: GM +0bp | E27: GM +15bp | F27: GM +30bp
A28: comps -2pp (FY24-29 revenue CAGR 4.6%) | B28: 298.921 | C28: 311.207 | D28: 323.494 | E28: 335.78 | F28: 348.066
A29: comps -1pp (FY24-29 revenue CAGR 5.6%) | B29: 304.283 | C29: 317.123 | D29: 329.962 | E29: 342.802 | F29: 355.641
A30: comps +0pp (FY24-29 revenue CAGR 6.6%) | B30: 309.857 | C30: 323.27 | D30: 336.684 | E30: 350.097 | F30: 363.51
A31: comps +1pp (FY24-29 revenue CAGR 7.6%) | B31: 315.649 | C31: 329.657 | D31: 343.666 | E31: 357.674 | F31: 371.683
A32: comps +2pp (FY24-29 revenue CAGR 8.6%) | B32: 321.666 | C32: 336.291 | D32: 350.916 | E32: 365.542 | F32: 380.167
A34: 4. Bear / base / bull (static values from src/sensitivity.py; set Assumptions!C5 to 1 or 3 to run a case live)
B35: Bear | C35: Base | D35: Bull
A36: FY24-29 revenue CAGR | B36: 0.0486635 | C36: 0.0655534 | D36: 0.07626
A37: FY2029 operating margin | B37: 0.0356714 | C37: 0.0376656 | D37: 0.038625
A38: Terminal growth | B38: 0.025 | C38: 0.03 | D38: 0.035
A39: Terminal RONIC | B39: 0.15 | C39: 0.25 | D39: 0.35
A40: Value per share ($) | B40: 263.396 | C40: 336.684 | D40: 400.229
A41: Probability | B41: 0.25 | C41: 0.5 | D41: 0.25
A42: Probability-weighted value ($) | B42: =SUMPRODUCT(B40:D40,B41:D41) -> 334.24825

Sheet Comps
A1: Comparable-company analysis, 31 Jan 2025 ($ millions)
A2: Independent academic research and valuation case study; not investment advice.
A3: Inputs (blue) from SEC XBRL company facts filed on or before 31 Jan 2025 and Yahoo Finance; LTM on a 52-week basis (src/ltm.py). EV excludes operating leases.
B5: Unit | C5: COST | D5: WMT | E5: BJ | F5: TGT | G5: DG | H5: DLTR | I5: KR
A6: Share price 31 Jan 2025 | B6: $ | C6: 979.88 | D6: 98.16 | E6: 99.05 | F6: 137.91 | G6: 71.06 | H6: 73.35 | I6: 61.64
A7: Shares outstanding (cover page) | B7: m | C7: 443.899 | D7: 8033.39 | E7: 132.094 | F7: 458.212 | G7: 219.926 | H7: 215.039 | I7: 723.606
A8: Debt incl. finance leases | B8: $m | C8: 7340 | D8: 47315 | E8: 678.351 | F8: 15981 | G8: 6242.4 | H8: 3430 | I8: 22617
A9: Noncontrolling interest | B9: $m | C9: 0 | D9: 6168 | E9: 0 | F9: 0 | G9: 0 | H9: 0 | I9: -6
A10: Cash and short-term investments | B10: $m | C10: 11827 | D10: 10049 | E10: 33.873 | F10: 3433 | G10: 537.257 | H10: 697.6 | I10: 13358
A11: LTM revenue | B11: $m | C11: 258805 | D11: 670137 | E11: 20192.2 | F11: 105540 | G11: 40166.3 | H11: 30630.6 | I11: 147051
A12: LTM operating income | B12: $m | C12: 9497 | D12: 28585.9 | E12: 792.576 | F12: 5851.47 | G12: 1999.52 | H12: -916.279 | I12: 4053.06
A13: LTM D&A | B13: $m | C13: 2284 | D13: 12646.5 | E13: 250.692 | F13: 2888.45 | G13: 941.069 | H13: 825.132 | I13: 3154.34
A14: LTM net income | B14: $m | C14: 7576 | D14: 19568.5 | E14: 547.106 | F14: 4287.55 | G14: 1335.85 | H14: -1024.3 | I14: 2714.79
A15: Revenue growth, YTD y/y | B15: % | C15: 0.0752954 | D15: 0.0541226 | E15: 0.0418764 | F15: 0.00209291 | G15: 0.0511466 | H15: 0.0280415 | I15: -0.00141624
A16: Revenue CAGR, 3 years | B16: % | C16: 0.091029 | D16: 0.0514113 | E16: 0.0828548 | F16: 0.0404674 | G16: 0.0466333 | H16: 0.0558481 | I16: 0.0357162
A18: Market capitalisation | C18: =C6*C7 -> 434967.75 | D18: =D6*D7 -> 788557.56 | E18: =E6*E7 -> 13083.911 | F18: =F6*F7 -> 63192.017 | G18: =G6*G7 -> 15627.942 | H18: =H6*H7 -> 15773.111 | I18: =I6*I7 -> 44603.074
A19: Enterprise value | C19: =C18+C8+C9-C10 -> 430480.75 | D19: =D18+D8+D9-D10 -> 831991.56 | E19: =E18+E8+E9-E10 -> 13728.389 | F19: =F18+F8+F9-F10 -> 75740.017 | G19: =G18+G8+G9-G10 -> 21333.085 | H19: =H18+H8+H9-H10 -> 18505.511 | I19: =I18+I8+I9-I10 -> 53856.074
A20: LTM EBITDA | C20: =C12+C13 -> 11781 | D20: =D12+D13 -> 41232.4 | E20: =E12+E13 -> 1043.268 | F20: =F12+F13 -> 8739.92 | G20: =G12+G13 -> 2940.589 | H20: =H12+H13 -> -91.147 | I20: =I12+I13 -> 7207.4
A21: EBITDA margin | C21: =C20/C11 -> 0.045520759 | D21: =D20/D11 -> 0.061528314 | E21: =E20/E11 -> 0.051666881 | F21: =F20/F11 -> 0.082811446 | G21: =G20/G11 -> 0.073210353 | H21: =H20/H11 -> -0.0029756844 | I21: =I20/I11 -> 0.049012927
A22: EV / Revenue | C22: =C19/C11 -> 1.6633402 | D22: =D19/D11 -> 1.2415246 | E22: =E19/E11 -> 0.67988573 | F22: =F19/F11 -> 0.71764276 | G22: =G19/G11 -> 0.53111899 | H22: =H19/H11 -> 0.6041511 | I22: =I19/I11 -> 0.36624079
A23: EV / EBITDA | C23: =IF(C20>0,C19/C20,"NM") -> 36.540256 | D23: =IF(D20>0,D19/D20,"NM") -> 20.178102 | E23: =IF(E20>0,E19/E20,"NM") -> 13.159024 | F23: =IF(F20>0,F19/F20,"NM") -> 8.6659851 | G23: =IF(G20>0,G19/G20,"NM") -> 7.2546978 | H23: =IF(H20>0,H19/H20,"NM") -> NM | I23: =IF(I20>0,I19/I20,"NM") -> 7.4723304
A24: P / E | C24: =IF(C14>0,C18/C14,"NM") -> 57.413906 | D24: =IF(D14>0,D18/D14,"NM") -> 40.297292 | E24: =IF(E14>0,E18/E14,"NM") -> 23.914764 | F24: =IF(F14>0,F18/F14,"NM") -> 14.738491 | G24: =IF(G14>0,G18/G14,"NM") -> 11.698875 | H24: =IF(H14>0,H18/H14,"NM") -> NM | I24: =IF(I14>0,I18/I14,"NM") -> 16.429659
A25: P / S | C25: =C18/C11 -> 1.6806775 | D25: =D18/D11 -> 1.176711 | E25: =E18/E11 -> 0.64796856 | F25: =F18/F11 -> 0.59874945 | G25: =G18/G11 -> 0.38908094 | H25: =H18/H11 -> 0.51494619 | I25: =I18/I11 -> 0.30331704
A26: Growth-adjusted EV/EBITDA | C26: =IF(ISNUMBER(C23),C23/(C16*100),"NM") -> 4.0141335 | D26: =IF(ISNUMBER(D23),D23/(D16*100),"NM") -> 3.9248379 | E26: =IF(ISNUMBER(E23),E23/(E16*100),"NM") -> 1.588203 | F26: =IF(ISNUMBER(F23),F23/(F16*100),"NM") -> 2.1414732 | G26: =IF(ISNUMBER(G23),G23/(G16*100),"NM") -> 1.5556904 | H26: =IF(ISNUMBER(H23),H23/(H16*100),"NM") -> NM | I26: =IF(ISNUMBER(I23),I23/(I16*100),"NM") -> 2.0921404
A27: Tier | C27: Subject | D27: Tier 1 | E27: Tier 1 | F27: Tier 2 | G27: Tier 3 | H27: Tier 3 | I27: Tier 2
A29: Peer statistics (excl. Costco) | C29: 25th pct | D29: Median | E29: 75th pct | F29: Tier 1 median | G29: Costco | H29: vs. median
A30: EV / Revenue | C30: =QUARTILE(D22:I22,1) -> 0.54937701 | D30: =MEDIAN(D22:I22) -> 0.64201842 | E30: =QUARTILE(D22:I22,3) -> 0.7082035 | F30: =MEDIAN(D22,E22) -> 0.96070516 | G30: =C22 -> 1.6633402 | H30: =G30/D30-1 -> 1.5907982
A31: EV / EBITDA | C31: =QUARTILE(D23:I23,1) -> 7.4723304 | D31: =MEDIAN(D23:I23) -> 8.6659851 | E31: =QUARTILE(D23:I23,3) -> 13.159024 | F31: =MEDIAN(D23,E23) -> 16.668563 | G31: =C23 -> 36.540256 | H31: =G31/D31-1 -> 3.2165149
A32: P / E | C32: =QUARTILE(D24:I24,1) -> 14.738491 | D32: =MEDIAN(D24:I24) -> 16.429659 | E32: =QUARTILE(D24:I24,3) -> 23.914764 | F32: =MEDIAN(D24,E24) -> 32.106028 | G32: =C24 -> 57.413906 | H32: =G32/D32-1 -> 2.4945282
A33: P / S | C33: =QUARTILE(D25:I25,1) -> 0.42054725 | D33: =MEDIAN(D25:I25) -> 0.55684782 | E33: =QUARTILE(D25:I25,3) -> 0.63566378 | F33: =MEDIAN(D25,E25) -> 0.91233977 | G33: =C25 -> 1.6806775 | H33: =G33/D33-1 -> 2.018199
A34: Growth-adjusted EV/EBITDA | C34: =QUARTILE(D26:I26,1) -> 1.588203 | D34: =MEDIAN(D26:I26) -> 2.0921404 | E34: =QUARTILE(D26:I26,3) -> 2.1414732 | F34: =MEDIAN(D26,E26) -> 2.7565204 | G34: =C26 -> 4.0141335 | H34: =G34/D34-1 -> 0.91867312
A36: Implied Costco value per share ($) | B36: Costco metric | C36: 25th pct | D36: Median | E36: 75th pct | F36: Tier 1 median
A37: EV / EBITDA | B37: =C20 -> 11781 | C37: =(C31*$B37+(C10-C8-C9))/C7 -> 208.42247 | D37: =(D31*$B37+(C10-C8-C9))/C7 -> 240.10185 | E37: =(E31*$B37+(C10-C8-C9))/C7 -> 359.3463 | F37: =(F31*$B37+(C10-C8-C9))/C7 -> 452.48883
A38: EV / Revenue | B38: =C11 -> 258805 | C38: =(C30*$B38+(C10-C8-C9))/C7 -> 330.40966 | D38: =(D30*$B38+(C10-C8-C9))/C7 -> 384.42208 | E38: =(E30*$B38+(C10-C8-C9))/C7 -> 423.00976 | F38: =(F30*$B38+(C10-C8-C9))/C7 -> 570.22498
A39: P / E | B39: =C14 -> 7576 | C39: =(C32*$B39)/C7 -> 251.54102 | D39: =(D32*$B39)/C7 -> 280.40409 | E39: =(E32*$B39)/C7 -> 408.15197 | F39: =(F32*$B39)/C7 -> 547.95183
A40: P / S | B40: =C11 -> 258805 | C40: =(C33*$B40)/C7 -> 245.1903 | D40: =(D33*$B40)/C7 -> 324.65718 | E40: =(E33*$B40)/C7 -> 370.609 | F40: =(F33*$B40)/C7 -> 531.91851

Sheet Summary
A1: Valuation summary ($ per share)
A2: Independent academic research and valuation case study; not investment advice.
A3: Football-field inputs; every number links to the sheet that computes it.
A5: Method | B5: Low | C5: Central | D5: High
A6: DCF: bear / base / bull | B6: =Sensitivity!B40 -> 263.396 | C6: =DCF!B48 -> 336.68367 | D6: =Sensitivity!D40 -> 400.229
A7: DCF: WACC +/-0.5pp, growth +/-0.5pp | B7: =MIN(Sensitivity!C11:E13) -> 294.22584 | C7: =DCF!B48 -> 336.68367 | D7: =MAX(Sensitivity!C11:E13) -> 398.1066
A8: Comps: EV/EBITDA (peer 25th-75th) | B8: =Comps!C37 -> 208.42247 | C8: =Comps!D37 -> 240.10185 | D8: =Comps!E37 -> 359.3463
A9: Comps: P/E (peer 25th-75th) | B9: =Comps!C39 -> 251.54102 | C9: =Comps!D39 -> 280.40409 | D9: =Comps!E39 -> 408.15197
A10: Comps: EV/Revenue (peer 25th-75th) | B10: =Comps!C38 -> 330.40966 | C10: =Comps!D38 -> 384.42208 | D10: =Comps!E38 -> 423.00976
A11: Comps: Tier 1 median (EV/EBITDA to P/E) | B11: =Comps!F37 -> 452.48883 | D11: =Comps!F39 -> 547.95183
A13: Share price, 31 Jan 2025 | C13: =DCF!B49 -> 979.88
A14: Probability-weighted DCF value | C14: =Sensitivity!B42 -> 334.24825
A15: DCF value vs. price | C15: =DCF!B50 -> -0.65640316

Sheet Checks
A1: Model checks
A2: Independent academic research and valuation case study; not investment advice.
A3: Integrity checks and a reconciliation of every headline number to the Python pipeline (outputs/tables). All flags should read OK.
A5: Check | B5: Excel | C5: Python / expected | D5: Difference | E5: Status
A6: Balance sheet balances, every year (sum of |check|) | B6: =SUMPRODUCT(ABS(Forecast!C54:H54)) -> 0 | C6: 0 | D6: =B6-C6 -> 0 | E6: =IF(ABS(D6)<=0.01,"OK","CHECK") -> OK
A7: Cash flow ties to balance-sheet cash, FY2025-29 | B7: =SUMPRODUCT(ABS(Forecast!D33:H33-Forecast!C33:G33-Forecast!D67:H67)) -> 0 | C7: 0 | D7: =B7-C7 -> 0 | E7: =IF(ABS(D7)<=0.01,"OK","CHECK") -> OK
A8: FY2024 revenue links to Historicals ($m) | B8: =Forecast!C18 -> 254453 | C8: 254453 | D8: =B8-C8 -> 0 | E8: =IF(ABS(D8)<=0.5,"OK","CHECK") -> OK
A9: FY2029 revenue ($m) | B9: =Forecast!H18 -> 349529.4 | C9: 349529 | D9: =B9-C9 -> 0.39617176 | E9: =IF(ABS(D9)<=0.5,"OK","CHECK") -> OK
A10: FY2029 operating income ($m) | B10: =Forecast!H21 -> 13165.218 | C10: 13165.2 | D10: =B10-C10 -> 0.018477528 | E10: =IF(ABS(D10)<=0.5,"OK","CHECK") -> OK
A11: FY2025 EPS ($) | B11: =Forecast!D28 -> 17.311728 | C11: 17.3117 | D11: =B11-C11 -> 2.7660276e-05 | E11: =IF(ABS(D11)<=0.005,"OK","CHECK") -> OK
A12: Raw beta | B12: =Beta!H6 -> 0.84262569 | C12: 0.84262569 | D12: =B12-C12 -> 0 | E12: =IF(ABS(D12)<=0.0005,"OK","CHECK") -> OK
A13: WACC | B13: =WACC!B27 -> 0.083824806 | C13: 0.083824806 | D13: =B13-C13 -> 0 | E13: =IF(ABS(D13)<=0.00005,"OK","CHECK") -> OK
A14: Enterprise value ($m) | B14: =DCF!B40 -> 145270.53 | C14: 145270.53 | D14: =B14-C14 -> 0 | E14: =IF(ABS(D14)<=1,"OK","CHECK") -> OK
A15: Value per share ($) | B15: =DCF!B48 -> 336.68367 | C15: 336.68367 | D15: =B15-C15 -> 0 | E15: =IF(ABS(D15)<=0.05,"OK","CHECK") -> OK
A16: Terminal value % of EV | B16: =DCF!B41 -> 0.81268184 | C16: 0.81268184 | D16: =B16-C16 -> 0 | E16: =IF(ABS(D16)<=0.0005,"OK","CHECK") -> OK
A17: Sensitivity grid centre = base value ($) | B17: =Sensitivity!D12 -> 336.68367 | C17: 336.68367 | D17: =B17-C17 -> 0 | E17: =IF(ABS(D17)<=0.05,"OK","CHECK") -> OK
A18: Comps: Costco EV/EBITDA | B18: =Comps!G31 -> 36.540256 | C18: 36.5402 | D18: =B18-C18 -> 5.5676089e-05 | E18: =IF(ABS(D18)<=0.005,"OK","CHECK") -> OK
A19: Comps: peer median EV/EBITDA | B19: =Comps!D31 -> 8.6659851 | C19: 8.66598 | D19: =B19-C19 -> 5.1486055e-06 | E19: =IF(ABS(D19)<=0.005,"OK","CHECK") -> OK
A20: Scenario selector is on Base (2) | B20: =Assumptions!C5 -> 2 | C20: 2 | D20: =B20-C20 -> 0 | E20: =IF(ABS(D20)<=0,"OK","CHECK") -> OK
A22: All checks | E22: =IF(COUNTIF(E6:E20,"OK")=15,"ALL OK","REVIEW") -> ALL OK
